Workbook

Sheet Summary
A1: Client Commitment Tracker
A2: Client Name : | C2: Alpla India Pvt Ltd (Silvassa)
A3: Engagement Manager : | C3: Mr. Nikhil Harwalkar
A4: Consultant : | C4: Mr. Nikhil Harwalkar and Mr. Yash Kandi
A5: Total Workshops Planned : | C5: 21st Jul 2024 to 9th Aug 2025
A6: Workshop wise Tracker | G6: Overall Journey Score
A7: Category | C7: WS 1 | D7: WS 2 | E7: WS 3 | F7: WS 4
A8: ='T & M (WS1)'!C29 -> Top Management Commitment | C8: ='T & M (WS1)'!D29 -> 0.76 | D8: ='T & M (WS2)'!D29 -> 0.88 | E8: ='T & M (WS3)'!D29 -> 0.88 | F8: ='T & M (WS4)'!D29 -> 0.88 | G8: =AVERAGE(C8:F8) -> 0.85
A9: ='T & M (WS1)'!C37 -> Departmental Heads' Commitment | C9: ='T & M (WS1)'!D37 -> 0.75 | D9: ='T & M (WS2)'!D37 -> 0.8 | E9: ='T & M (WS3)'!D37 -> 0.8 | F9: ='T & M (WS4)'!D37 -> 0.8 | G9: =AVERAGE(C9:F9) -> 0.7875
A10: ='T & M (WS1)'!C45 -> Managerial Team's Commitment | C10: ='T & M (WS1)'!D45 -> 0.8 | D10: ='T & M (WS2)'!D45 -> 0.6 | E10: ='T & M (WS3)'!D45 -> 0.6 | F10: ='T & M (WS4)'!D45 -> 0.6 | G10: =AVERAGE(C10:F10) -> 0.65
A11: Administrative support | C11: ='T & M (WS1)'!D53 -> 0.68 | D11: ='T & M (WS2)'!D53 -> 1 | E11: ='T & M (WS3)'!D53 -> 1 | F11: ='T & M (WS4)'!D53 -> 1 | G11: =AVERAGE(C11:F11) -> 0.92
A12: Client Commitment Score | C12: ='T & M (WS1)'!D56 -> 0.74117647 | D12: ='T & M (WS2)'!D56 -> 0.84705882 | E12: ='T & M (WS3)'!D56 -> 0.84705882 | F12: ='T & M (WS4)'!D56 -> 0.84705882 | G12: =AVERAGE(C12:F12) -> 0.82058824

Sheet T & M (WS1)
A1: Client Commitment Tracker
A2: Client Name : | C2: iD Fresh Food India Pvt Ltd
A3: Workshop No. : | C3: 1
A4: Engagement Manager : | C4: Mr. Basavaraj Gudi
A5: Consultant : | C5: Mr. Nikhil Harwalkar
A6: Workshop Date : | C6: 15th to 27th Dec 2025
M15: Pointer
M16: Value | N16: =D56 -> 0.74117647
M17: Point | N17: 0.02
M18: Remain | N18: =200%-(N16+N17) -> 1.2388235
M20: Circle
A21: Sr no | B21: Category | C21: Particulars | D21: Score | F21: Criteria | M21: Very Poor | N21: 20
A22: 1 | B22: Top Management Commitment | C22: Does Top Management review project with consultants? | D22: 4 | F22: Outstanding | G22: 5 | M22: Poor | N22: 20
A23: =A22+1 -> 2 | C23: Does Top Management visit Gemba on a fortnightly basis? | D23: 4 | F23: Satisfactory | G23: 4 | M23: Average | N23: 20
A24: =A23+1 -> 3 | C24: Does Top Management attend opening & closing meeting of workshops? | D24: 4 | F24: Needs Improvement | G24: 3 | M24: Good | N24: 20
A25: =A24+1 -> 4 | C25: Does top management actively communicate the importance of Time & Motion Studies to the organization? | D25: 4 | F25: Unsatisfactory | G25: 2 | M25: Very Good | N25: 20
A26: =A25+1 -> 5 | C26: Does Top Management give workshop feedback on time to Quality? | D26: 3 | F26: Disappointing | G26: 1 | M26: Remain | N26: 100
C27: Total | D27: =SUM(D22:D26) -> 19
C28: Maximum Score | D28: =COUNT(A22:A26)*$G$22 -> 25
C29: Top Management Commitment | D29: =D27/D28 -> 0.76
A30: =A26+1 -> 6 | B30: Departmental Heads' Commitment | C30: Rate the Departmental Head's accessibility and provision of necessary data on time | D30: 4
A32: =A30+1 -> 7 | C32: The Departmental Head's involvement in addressing challenges related to data availability? | D32: 3
A33: =A32+1 -> 8 | C33: The Departmental Head's support for trying new ways of collecting and analysing data. | D33: 4
A34: =A33+1 -> 9 | C34: The Departmental Head's support in identifying and addressing gaps in data availability | D34: 4
C35: Total | D35: =SUM(D30:D34) -> 15
C36: Maximum Score | D36: =COUNT(A30:A34)*$G$22 -> 20
C37: Departmental Heads' Commitment | D37: =D35/D36 -> 0.75
A38: =A34+1 -> 10 | B38: Managerial Team | C38: Are team members available full time to drive projects during workshop? | D38: 4
A39: =A38+1 -> 11 | C39: How committed is the project team towards process improvement? | D39: 4
A40: =A39+1 -> 12 | C40: Rate the White Collar Team's proactiveness in seeking additional data or information related to their tasks. | D40: 4
C43: Total | D43: =SUM(D38:D42) -> 12
C44: Maximum Score | D44: =COUNT(A38:A42)*$G$22 -> 15
C45: Managerial Team's Commitment | D45: =D43/D44 -> 0.8
A46: =A40+1 -> 13 | B46: Administrative Support | C46: Are travel arrangements done in convenient manner? | D46: 2
A47: =A46+1 -> 14 | C47: Is client team supporting Faber Travel desk on time? | D47: 3
A48: =A47+1 -> 15 | C48: Is dedicated workstation given to consulting team? | D48: 4
A49: =A48+1 -> 16 | C49: Has the team been provided with necessary supplies and internet access? | D49: 4
A50: =A49+1 -> 17 | C50: Is accommodation arrangement done properly? | D50: 4
C51: Total | D51: =SUM(D46:D50) -> 17
C52: Maximum Score | D52: =COUNT(A46:A50)*$G$22 -> 25
...

Sheet T & M (WS2)
A1: Client Commitment Tracker
A2: Client Name :
A3: Workshop No. :
A4: Engagement Manager :
A5: Consultant :
A6: Workshop Date :
M15: Pointer
M16: Value | N16: =D56 -> 0.84705882
M17: Point | N17: 0.02
M18: Remain | N18: =200%-(N16+N17) -> 1.1329412
M20: Circle
A21: Sr no | B21: Category | C21: Particulars | D21: Score | F21: Criteria | M21: Very Poor | N21: 20
A22: 1 | B22: Top Management Commitment | C22: Does Top Management reviews project with consultants? | D22: 5 | F22: Outstanding | G22: 5 | M22: Poor | N22: 20
A23: =A22+1 -> 2 | C23: Does Top Management visit Gemba on a fortnightly basis? | D23: 4 | F23: Satisfactory | G23: 4 | M23: Average | N23: 20
A24: =A23+1 -> 3 | C24: Does Top Management attend opening & closing meeting of workshops? | D24: 5 | F24: Needs Improvement | G24: 3 | M24: Good | N24: 20
A25: =A24+1 -> 4 | C25: Does top management actively communicate the importance of Time & Motion Studies to the organization? | D25: 4 | F25: Unsatisfactory | G25: 2 | M25: Very Good | N25: 20
A26: =A25+1 -> 5 | C26: Does Top Management give workshop feedback on time to Quality? | D26: 4 | F26: Disappointing | G26: 1 | M26: Remain | N26: 100
C27: Total | D27: =SUM(D22:D26) -> 22
C28: Maximum Score | D28: =COUNT(A22:A26)*$G$22 -> 25
C29: Top Management Commitment | D29: =D27/D28 -> 0.88
A30: =A26+1 -> 6 | B30: Departmental Heads' Commitment | C30: Rate the Departmental Head's accessibility and provision of necessary data on time | D30: 4
A32: =A30+1 -> 7 | C32: The Departmental Head's involvement in addressing challenges related to data availability ? | D32: 4
A33: =A32+1 -> 8 | C33: The Departmental Head's support for trying new ways of collecting and analyzing data. | D33: 4
A34: =A33+1 -> 9 | C34: The Departmental Head's support in identifying and addressing gaps in data availability | D34: 4
C35: Total | D35: =SUM(D30:D34) -> 16
C36: Maximum Score | D36: =COUNT(A30:A34)*$G$22 -> 20
C37: Departmental Heads' Commitment | D37: =D35/D36 -> 0.8
A38: =A34+1 -> 10 | B38: Managerial Team | C38: Are team members available full time to drive projects during workshop? | D38: 3
A39: =A38+1 -> 11 | C39: How committed is the project team to for process improvement? | D39: 3
A40: =A39+1 -> 12 | C40: Rate the White Collar Team's proactiveness in seeking additional data or information related to their tasks. | D40: 3
C43: Total | D43: =SUM(D38:D42) -> 9
C44: Maximum Score | D44: =COUNT(A38:A42)*$G$22 -> 15
C45: Managerial Team's Commitment | D45: =D43/D44 -> 0.6
A46: =A40+1 -> 13 | B46: Administrative Support | C46: Are travel arrangements have been done in convenient manner? | D46: 5
A47: =A46+1 -> 14 | C47: Does client team is supporting Faber Travel desk on time? | D47: 5
A48: =A47+1 -> 15 | C48: Is dedicated workstation has been given to consulting team? | D48: 5
A49: =A48+1 -> 16 | C49: Has the team been provided with necessary supplies and internet access? | D49: 5
A50: =A49+1 -> 17 | C50: Is accommodation arrangement done properly? | D50: 5
C51: Total | D51: =SUM(D46:D50) -> 25
C52: Maximum Score | D52: =COUNT(A46:A50)*$G$22 -> 25
...

Sheet T & M (WS3)
A1: Client Commitment Tracker
A2: Client Name :
A3: Workshop No. :
A4: Engagement Manager :
A5: Consultant :
A6: Workshop Date :
M15: Pointer
M16: Value | N16: =D56 -> 0.84705882
M17: Point | N17: 0.02
M18: Remain | N18: =200%-(N16+N17) -> 1.1329412
M20: Circle
A21: Sr no | B21: Category | C21: Particulars | D21: Score | F21: Criteria | M21: Very Poor | N21: 20
A22: 1 | B22: Top Management Commitment | C22: Does Top Management reviews project with consultants? | D22: 5 | F22: Outstanding | G22: 5 | M22: Poor | N22: 20
A23: =A22+1 -> 2 | C23: Does Top Management visit Gemba on a fortnightly basis? | D23: 4 | F23: Satisfactory | G23: 4 | M23: Average | N23: 20
A24: =A23+1 -> 3 | C24: Does Top Management attend opening & closing meeting of workshops? | D24: 5 | F24: Needs Improvement | G24: 3 | M24: Good | N24: 20
A25: =A24+1 -> 4 | C25: Does top management actively communicate the importance of Time & Motion Studies to the organization? | D25: 4 | F25: Unsatisfactory | G25: 2 | M25: Very Good | N25: 20
A26: =A25+1 -> 5 | C26: Does Top Management give workshop feedback on time to Quality? | D26: 4 | F26: Disappointing | G26: 1 | M26: Remain | N26: 100
C27: Total | D27: =SUM(D22:D26) -> 22
C28: Maximum Score | D28: =COUNT(A22:A26)*$G$22 -> 25
C29: Top Management Commitment | D29: =D27/D28 -> 0.88
A30: =A26+1 -> 6 | B30: Departmental Heads' Commitment | C30: Rate the Departmental Head's accessibility and provision of necessary data on time | D30: 4
A32: =A30+1 -> 7 | C32: The Departmental Head's involvement in addressing challenges related to data availability ? | D32: 4
A33: =A32+1 -> 8 | C33: The Departmental Head's support for trying new ways of collecting and analyzing data. | D33: 4
A34: =A33+1 -> 9 | C34: The Departmental Head's support in identifying and addressing gaps in data availability | D34: 4
C35: Total | D35: =SUM(D30:D34) -> 16
C36: Maximum Score | D36: =COUNT(A30:A34)*$G$22 -> 20
C37: Departmental Heads' Commitment | D37: =D35/D36 -> 0.8
A38: =A34+1 -> 10 | B38: Managerial Team | C38: Are team members available full time to drive projects during workshop? | D38: 3
A39: =A38+1 -> 11 | C39: How committed is the project team to for process improvement? | D39: 3
A40: =A39+1 -> 12 | C40: Rate the White Collar Team's proactiveness in seeking additional data or information related to their tasks. | D40: 3
C43: Total | D43: =SUM(D38:D42) -> 9
C44: Maximum Score | D44: =COUNT(A38:A42)*$G$22 -> 15
C45: Managerial Team's Commitment | D45: =D43/D44 -> 0.6
A46: =A40+1 -> 13 | B46: Administrative Support | C46: Are travel arrangements have been done in convenient manner? | D46: 5
A47: =A46+1 -> 14 | C47: Does client team is supporting Faber Travel desk on time? | D47: 5
A48: =A47+1 -> 15 | C48: Is dedicated workstation has been given to consulting team? | D48: 5
A49: =A48+1 -> 16 | C49: Has the team been provided with necessary supplies and internet access? | D49: 5
A50: =A49+1 -> 17 | C50: Is accommodation arrangement done properly? | D50: 5
C51: Total | D51: =SUM(D46:D50) -> 25
C52: Maximum Score | D52: =COUNT(A46:A50)*$G$22 -> 25
...

Sheet T & M (WS4)
A1: Client Commitment Tracker
A2: Client Name :
A3: Workshop No. :
A4: Engagement Manager :
A5: Consultant :
A6: Workshop Date :
M15: Pointer
M16: Value | N16: =D56 -> 0.84705882
M17: Point | N17: 0.02
M18: Remain | N18: =200%-(N16+N17) -> 1.1329412
M20: Circle
A21: Sr no | B21: Category | C21: Particulars | D21: Score | F21: Criteria | M21: Very Poor | N21: 20
A22: 1 | B22: Top Management Commitment | C22: Does Top Management reviews project with consultants? | D22: 5 | F22: Outstanding | G22: 5 | M22: Poor | N22: 20
A23: =A22+1 -> 2 | C23: Does Top Management visit Gemba on a fortnightly basis? | D23: 4 | F23: Satisfactory | G23: 4 | M23: Average | N23: 20
A24: =A23+1 -> 3 | C24: Does Top Management attend opening & closing meeting of workshops? | D24: 5 | F24: Needs Improvement | G24: 3 | M24: Good | N24: 20
A25: =A24+1 -> 4 | C25: Does top management actively communicate the importance of Time & Motion Studies to the organization? | D25: 4 | F25: Unsatisfactory | G25: 2 | M25: Very Good | N25: 20
A26: =A25+1 -> 5 | C26: Does Top Management give workshop feedback on time to Quality? | D26: 4 | F26: Disappointing | G26: 1 | M26: Remain | N26: 100
C27: Total | D27: =SUM(D22:D26) -> 22
C28: Maximum Score | D28: =COUNT(A22:A26)*$G$22 -> 25
C29: Top Management Commitment | D29: =D27/D28 -> 0.88
A30: =A26+1 -> 6 | B30: Departmental Heads' Commitment | C30: Rate the Departmental Head's accessibility and provision of necessary data on time | D30: 4
A32: =A30+1 -> 7 | C32: The Departmental Head's involvement in addressing challenges related to data availability ? | D32: 4
A33: =A32+1 -> 8 | C33: The Departmental Head's support for trying new ways of collecting and analyzing data. | D33: 4
A34: =A33+1 -> 9 | C34: The Departmental Head's support in identifying and addressing gaps in data availability | D34: 4
C35: Total | D35: =SUM(D30:D34) -> 16
C36: Maximum Score | D36: =COUNT(A30:A34)*$G$22 -> 20
C37: Departmental Heads' Commitment | D37: =D35/D36 -> 0.8
A38: =A34+1 -> 10 | B38: Managerial Team | C38: Are team members available full time to drive projects during workshop? | D38: 3
A39: =A38+1 -> 11 | C39: How committed is the project team to for process improvement? | D39: 3
A40: =A39+1 -> 12 | C40: Rate the White Collar Team's proactiveness in seeking additional data or information related to their tasks. | D40: 3
C43: Total | D43: =SUM(D38:D42) -> 9
C44: Maximum Score | D44: =COUNT(A38:A42)*$G$22 -> 15
C45: Managerial Team's Commitment | D45: =D43/D44 -> 0.6
A46: =A40+1 -> 13 | B46: Administrative Support | C46: Are travel arrangements have been done in convenient manner? | D46: 5
A47: =A46+1 -> 14 | C47: Does client team is supporting Faber Travel desk on time? | D47: 5
A48: =A47+1 -> 15 | C48: Is dedicated workstation has been given to consulting team? | D48: 5
A49: =A48+1 -> 16 | C49: Has the team been provided with necessary supplies and internet access? | D49: 5
A50: =A49+1 -> 17 | C50: Is accommodation arrangement done properly? | D50: 5
C51: Total | D51: =SUM(D46:D50) -> 25
C52: Maximum Score | D52: =COUNT(A46:A50)*$G$22 -> 25
...

Sheet Key to Score
B1: Criteria | D1: Interpretation
B2: Outstanding | C2: 5 | D2: Follows rigorously as well as give additional contribution
B3: Satisfactory | C3: 4 | D3: Follows rigorously every time
B4: Needs Improvement | C4: 3 | D4: Follows but not rigorous, intermittent deterioration
B5: Unsatisfactory | C5: 2 | D5: Needs continuous follow-up from consultants
B6: Disappointing | C6: 1 | D6: No involvement & No contribution, Reluctant to change

Sheet WS 10
A1: Client Commitment Tracker
A2: Client Name : | C2: ='T & M (WS1)'!C2 -> iD Fresh Food India Pvt Ltd
A3: Workshop No. : | C3: 10
A4: Engagement Manager : | C4: ABC
A5: Consultant : | C5: PQR
A6: Workshop Date : | C6: 01-Feb-2023 to 08-Feb-2023
M15: Pointer
M16: Value | N16: =D64 -> 0
M17: Point | N17: 0.02
M18: Remain | N18: =200%-(N16+N17) -> 1.98
M20: Circle
A21: Sr no | B21: Category | C21: Particulars | D21: Score | F21: Criteria | M21: Very Poor | N21: 35
A22: 1 | B22: Top Management Commitment | C22: ='T & M (WS1)'!C22 -> Does Top Management review project with consultants? | F22: Outstanding | G22: 5 | M22: Poor | N22: 20
A23: =A22+1 -> 2 | C23: ='T & M (WS1)'!C23 -> Does Top Management visit Gemba on a fortnightly basis? | F23: Satisfactory | G23: 4 | M23: Average | N23: 20
A24: =A23+1 -> 3 | C24: ='T & M (WS1)'!C24 -> Does Top Management attend opening & closing meeting of workshops? | F24: Needs Improvement | G24: 3 | M24: Good | N24: 15
A25: =A24+1 -> 4 | C25: ='T & M (WS1)'!C25 -> Does top management actively communicate the importance of Time & Motion Studies to the organization? | F25: Unsatisfactory | G25: 2 | M25: Very Good | N25: 10
A26: =A25+1 -> 5 | C26: ='T & M (WS1)'!C26 -> Does Top Management give workshop feedback on time to Quality? | F26: Disappointing | G26: 1 | M26: Remain | N26: 100
C27: ='T & M (WS1)'!C27 -> Total | D27: =SUM(D22:D26) -> 0
C28: ='T & M (WS1)'!C28 -> Maximum Score | D28: =COUNT(A22:A26)*$G$22 -> 25
C29: ='T & M (WS1)'!C29 -> Top Management Commitment | D29: =D27/D28 -> 0
A30: =A26+1 -> 6 | B30: Steering Committee Commitment | C30: ='T & M (WS1)'!#REF! -> #REF!
A31: =A30+1 -> 7 | C31: ='T & M (WS1)'!C30 -> Rate the Departmental Head's accessibility and provision of necessary data on time
A32: =A31+1 -> 8 | C32: ='T & M (WS1)'!C32 -> The Departmental Head's involvement in addressing challenges related to data availability?
A33: =A32+1 -> 9 | C33: ='T & M (WS1)'!C33 -> The Departmental Head's support for trying new ways of collecting and analysing data.
A34: =A33+1 -> 10 | C34: ='T & M (WS1)'!C34 -> The Departmental Head's support in identifying and addressing gaps in data availability
C35: ='T & M (WS1)'!C35 -> Total | D35: =SUM(D30:D34) -> 0
C36: ='T & M (WS1)'!C36 -> Maximum Score | D36: =COUNT(A30:A34)*$G$22 -> 25
C37: ='T & M (WS1)'!C37 -> Departmental Heads' Commitment | D37: =D35/D36 -> 0
A38: =A34+1 -> 11 | B38: Project Team Commitment | C38: ='T & M (WS1)'!C38 -> Are team members available full time to drive projects during workshop?
A39: =A38+1 -> 12 | C39: ='T & M (WS1)'!C39 -> How committed is the project team towards process improvement?
A40: =A39+1 -> 13 | C40: ='T & M (WS1)'!C40 -> Rate the White Collar Team's proactiveness in seeking additional data or information related to their tasks.
A41: =A40+1 -> 14 | C41: ='T & M (WS1)'!C41 -> 0
A42: =A41+1 -> 15 | C42: ='T & M (WS1)'!C42 -> 0
C43: ='T & M (WS1)'!C43 -> Total | D43: =SUM(D38:D42) -> 0
C44: ='T & M (WS1)'!C44 -> Maximum Score | D44: =COUNT(A38:A42)*$G$22 -> 25
C45: ='T & M (WS1)'!C45 -> Managerial Team's Commitment | D45: =D43/D44 -> 0
A46: =A42+1 -> 16 | B46: Employee Morale | C46: ='T & M (WS1)'!C46 -> Are travel arrangements done in convenient manner?
A47: =A46+1 -> 17 | C47: ='T & M (WS1)'!C47 -> Is client team supporting Faber Travel desk on time?
A48: =A47+1 -> 18 | C48: ='T & M (WS1)'!C48 -> Is dedicated workstation given to consulting team?
A49: =A48+1 -> 19 | C49: ='T & M (WS1)'!C49 -> Has the team been provided with necessary supplies and internet access?
...

Sheet WS 11
A1: Client Commitment Tracker
A2: Client Name : | C2: ='T & M (WS1)'!C2 -> iD Fresh Food India Pvt Ltd
A3: Workshop No. : | C3: 11
A4: Engagement Manager : | C4: ABC
A5: Consultant : | C5: PQR
A6: Workshop Date : | C6: 01-Feb-2023 to 08-Feb-2023
M15: Pointer
M16: Value | N16: =D64 -> 0
M17: Point | N17: 0.02
M18: Remain | N18: =200%-(N16+N17) -> 1.98
M20: Circle
A21: Sr no | B21: Category | C21: Particulars | D21: Score | F21: Criteria | M21: Very Poor | N21: 35
A22: 1 | B22: Top Management Commitment | C22: ='T & M (WS1)'!C22 -> Does Top Management review project with consultants? | F22: Outstanding | G22: 5 | M22: Poor | N22: 20
A23: =A22+1 -> 2 | C23: ='T & M (WS1)'!C23 -> Does Top Management visit Gemba on a fortnightly basis? | F23: Satisfactory | G23: 4 | M23: Average | N23: 20
A24: =A23+1 -> 3 | C24: ='T & M (WS1)'!C24 -> Does Top Management attend opening & closing meeting of workshops? | F24: Needs Improvement | G24: 3 | M24: Good | N24: 15
A25: =A24+1 -> 4 | C25: ='T & M (WS1)'!C25 -> Does top management actively communicate the importance of Time & Motion Studies to the organization? | F25: Unsatisfactory | G25: 2 | M25: Very Good | N25: 10
A26: =A25+1 -> 5 | C26: ='T & M (WS1)'!C26 -> Does Top Management give workshop feedback on time to Quality? | F26: Disappointing | G26: 1 | M26: Remain | N26: 100
C27: ='T & M (WS1)'!C27 -> Total | D27: =SUM(D22:D26) -> 0
C28: ='T & M (WS1)'!C28 -> Maximum Score | D28: =COUNT(A22:A26)*$G$22 -> 25
C29: ='T & M (WS1)'!C29 -> Top Management Commitment | D29: =D27/D28 -> 0
A30: =A26+1 -> 6 | B30: Steering Committee Commitment | C30: ='T & M (WS1)'!#REF! -> #REF!
A31: =A30+1 -> 7 | C31: ='T & M (WS1)'!C30 -> Rate the Departmental Head's accessibility and provision of necessary data on time
A32: =A31+1 -> 8 | C32: ='T & M (WS1)'!C32 -> The Departmental Head's involvement in addressing challenges related to data availability?
A33: =A32+1 -> 9 | C33: ='T & M (WS1)'!C33 -> The Departmental Head's support for trying new ways of collecting and analysing data.
A34: =A33+1 -> 10 | C34: ='T & M (WS1)'!C34 -> The Departmental Head's support in identifying and addressing gaps in data availability
C35: ='T & M (WS1)'!C35 -> Total | D35: =SUM(D30:D34) -> 0
C36: ='T & M (WS1)'!C36 -> Maximum Score | D36: =COUNT(A30:A34)*$G$22 -> 25
C37: ='T & M (WS1)'!C37 -> Departmental Heads' Commitment | D37: =D35/D36 -> 0
A38: =A34+1 -> 11 | B38: Project Team Commitment | C38: ='T & M (WS1)'!C38 -> Are team members available full time to drive projects during workshop?
A39: =A38+1 -> 12 | C39: ='T & M (WS1)'!C39 -> How committed is the project team towards process improvement?
A40: =A39+1 -> 13 | C40: ='T & M (WS1)'!C40 -> Rate the White Collar Team's proactiveness in seeking additional data or information related to their tasks.
A41: =A40+1 -> 14 | C41: ='T & M (WS1)'!C41 -> 0
A42: =A41+1 -> 15 | C42: ='T & M (WS1)'!C42 -> 0
C43: ='T & M (WS1)'!C43 -> Total | D43: =SUM(D38:D42) -> 0
C44: ='T & M (WS1)'!C44 -> Maximum Score | D44: =COUNT(A38:A42)*$G$22 -> 25
C45: ='T & M (WS1)'!C45 -> Managerial Team's Commitment | D45: =D43/D44 -> 0
A46: =A42+1 -> 16 | B46: Employee Morale | C46: ='T & M (WS1)'!C46 -> Are travel arrangements done in convenient manner?
A47: =A46+1 -> 17 | C47: ='T & M (WS1)'!C47 -> Is client team supporting Faber Travel desk on time?
A48: =A47+1 -> 18 | C48: ='T & M (WS1)'!C48 -> Is dedicated workstation given to consulting team?
A49: =A48+1 -> 19 | C49: ='T & M (WS1)'!C49 -> Has the team been provided with necessary supplies and internet access?
...

Sheet WS 12
A1: Client Commitment Tracker
A2: Client Name : | C2: ='T & M (WS1)'!C2 -> iD Fresh Food India Pvt Ltd
A3: Workshop No. : | C3: 12
A4: Engagement Manager : | C4: ABC
A5: Consultant : | C5: PQR
A6: Workshop Date : | C6: 01-Feb-2023 to 08-Feb-2023
M15: Pointer
M16: Value | N16: =D64 -> 0
M17: Point | N17: 0.02
M18: Remain | N18: =200%-(N16+N17) -> 1.98
M20: Circle
A21: Sr no | B21: Category | C21: Particulars | D21: Score | F21: Criteria | M21: Very Poor | N21: 35
A22: 1 | B22: Top Management Commitment | C22: ='T & M (WS1)'!C22 -> Does Top Management review project with consultants? | F22: Outstanding | G22: 5 | M22: Poor | N22: 20
A23: =A22+1 -> 2 | C23: ='T & M (WS1)'!C23 -> Does Top Management visit Gemba on a fortnightly basis? | F23: Satisfactory | G23: 4 | M23: Average | N23: 20
A24: =A23+1 -> 3 | C24: ='T & M (WS1)'!C24 -> Does Top Management attend opening & closing meeting of workshops? | F24: Needs Improvement | G24: 3 | M24: Good | N24: 15
A25: =A24+1 -> 4 | C25: ='T & M (WS1)'!C25 -> Does top management actively communicate the importance of Time & Motion Studies to the organization? | F25: Unsatisfactory | G25: 2 | M25: Very Good | N25: 10
A26: =A25+1 -> 5 | C26: ='T & M (WS1)'!C26 -> Does Top Management give workshop feedback on time to Quality? | F26: Disappointing | G26: 1 | M26: Remain | N26: 100
C27: ='T & M (WS1)'!C27 -> Total | D27: =SUM(D22:D26) -> 0
C28: ='T & M (WS1)'!C28 -> Maximum Score | D28: =COUNT(A22:A26)*$G$22 -> 25
C29: ='T & M (WS1)'!C29 -> Top Management Commitment | D29: =D27/D28 -> 0
A30: =A26+1 -> 6 | B30: Steering Committee Commitment | C30: ='T & M (WS1)'!#REF! -> #REF!
A31: =A30+1 -> 7 | C31: ='T & M (WS1)'!C30 -> Rate the Departmental Head's accessibility and provision of necessary data on time
A32: =A31+1 -> 8 | C32: ='T & M (WS1)'!C32 -> The Departmental Head's involvement in addressing challenges related to data availability?
A33: =A32+1 -> 9 | C33: ='T & M (WS1)'!C33 -> The Departmental Head's support for trying new ways of collecting and analysing data.
A34: =A33+1 -> 10 | C34: ='T & M (WS1)'!C34 -> The Departmental Head's support in identifying and addressing gaps in data availability
C35: ='T & M (WS1)'!C35 -> Total | D35: =SUM(D30:D34) -> 0
C36: ='T & M (WS1)'!C36 -> Maximum Score | D36: =COUNT(A30:A34)*$G$22 -> 25
C37: ='T & M (WS1)'!C37 -> Departmental Heads' Commitment | D37: =D35/D36 -> 0
A38: =A34+1 -> 11 | B38: Project Team Commitment | C38: ='T & M (WS1)'!C38 -> Are team members available full time to drive projects during workshop?
A39: =A38+1 -> 12 | C39: ='T & M (WS1)'!C39 -> How committed is the project team towards process improvement?
A40: =A39+1 -> 13 | C40: ='T & M (WS1)'!C40 -> Rate the White Collar Team's proactiveness in seeking additional data or information related to their tasks.
A41: =A40+1 -> 14 | C41: ='T & M (WS1)'!C41 -> 0
A42: =A41+1 -> 15 | C42: ='T & M (WS1)'!C42 -> 0
C43: ='T & M (WS1)'!C43 -> Total | D43: =SUM(D38:D42) -> 0
C44: ='T & M (WS1)'!C44 -> Maximum Score | D44: =COUNT(A38:A42)*$G$22 -> 25
C45: ='T & M (WS1)'!C45 -> Managerial Team's Commitment | D45: =D43/D44 -> 0
A46: =A42+1 -> 16 | B46: Employee Morale | C46: ='T & M (WS1)'!C46 -> Are travel arrangements done in convenient manner?
A47: =A46+1 -> 17 | C47: ='T & M (WS1)'!C47 -> Is client team supporting Faber Travel desk on time?
A48: =A47+1 -> 18 | C48: ='T & M (WS1)'!C48 -> Is dedicated workstation given to consulting team?
A49: =A48+1 -> 19 | C49: ='T & M (WS1)'!C49 -> Has the team been provided with necessary supplies and internet access?
...
